{
  "comments": [
    {
      "key": {
        "uuid": "5a682502_645f9473",
        "filename": "docs/release/userguide/docker.userguide.rst",
        "patchSetId": 3
      },
      "lineNbr": 176,
      "author": {
        "id": 6421
      },
      "writtenOn": "2018-09-10T17:31:49Z",
      "side": 1,
      "message": "Error while running playbook...\n\nTASK [config_files : copy types.db to target system] *************************************************************************************************************************************************************************************************************\nAn exception occurred during task execution. To see the full traceback, use -vvv. The error was: If you are using a module and expect the file to exist on the remote, see the remote_src option\nfatal: [localhost]: FAILED! \u003d\u003e {\"changed\": false, \"msg\": \"Could not find or access \u0027types.db\u0027\\nSearched in:\\n\\t/root/barometer/docker/ansible/roles/config_files/files/types.db\\n\\t/root/barometer/docker/ansible/roles/config_files/types.db\\n\\t/root/barometer/docker/ansible/roles/config_files/tasks/files/types.db\\n\\t/root/barometer/docker/ansible/roles/config_files/tasks/types.db\\n\\t/root/barometer/docker/ansible/files/types.db\\n\\t/root/barometer/docker/ansible/types.db on the Ansible Controller.\\nIf you are using a module and expect the file to exist on the remote, see the remote_src option\"}",
      "revId": "75bd7bfe59623137cf38f2c21f1798f034237fad",
      "serverId": "bbac25d2-bf60-4904-9ba8-a72fc000d6c5",
      "unresolved": false
    }
  ]
}